Workbook

Sheet Исходные данные
A1: Год | B1: Объем инвестиций в основной капитал, направленный на цифровизацию, млрд. руб. | C1: Доля безналичных платежей, % | D1: Пользователи интернета, % на 100 человек | E1: Объем рынка e-commerce, млрд. руб.
B2: X1 | C2: X2 | D2: X3 | E2: Y
A3: 2006 | B3: 100 | C3: 3.25 | D3: 17.57 | E3: 29.3
A4: 2007 | B4: 135.4 | C4: 5 | D4: 24.6 | E4: 95.35
A5: 2008 | B5: 150 | C5: 9 | D5: 28.1 | E5: 128.31
A6: 2009 | B6: 158.34 | C6: 9.3 | D6: 29.6 | E6: 150
A7: 2010 | B7: 170.255 | C7: 11 | D7: 39.9 | E7: 260
A8: 2011 | B8: 248.64 | C8: 18.7 | D8: 58 | E8: 330
A9: 2012 | B9: 293.66 | C9: 23.3 | D9: 66 | E9: 405
A10: 2013 | B10: 283.42 | C10: 27 | D10: 68 | E10: 544
A11: 2014 | B11: 292.15 | C11: 33.1 | D11: 71 | E11: 713
A12: 2015 | B12: 304.98 | C12: 39.7 | D12: 70.1 | E12: 760
A13: 2016 | B13: 284.67 | C13: 47.1 | D13: 73.09 | E13: 920
A14: 2017 | B14: 389.6 | C14: 57.7 | D14: 76.01 | E14: 1040
... A20: 2023 | B20: 1161.6 | C20: 83.4 | D20: 89.2 | E20: 6359

Sheet Корреляционный анализ
A1: Год | B1: Объем инвестиций в основной капитал, направленный на цифровизацию, млрд. руб. | C1: Доля безналичных платежей, % | D1: Пользователи интернета, % на 100 человек | E1: Объем рынка e-commerce, млрд. руб.
A2: 2006 | B2: 100 | C2: 3.25 | D2: 17.57 | E2: 29.3
A3: 2007 | B3: 135.4 | C3: 5 | D3: 24.6 | E3: 95.35
A4: 2008 | B4: 150 | C4: 9 | D4: 28.1 | E4: 128.31
A5: 2009 | B5: 158.34 | C5: 9.3 | D5: 29.6 | E5: 150
A6: 2010 | B6: 170.255 | C6: 11 | D6: 39.9 | E6: 260
A7: 2011 | B7: 248.64 | C7: 18.7 | D7: 58 | E7: 330
A8: =A7+1 -> 2012 | B8: 293.66 | C8: 23.3 | D8: 66 | E8: 405
A9: =A8+1 -> 2013 | B9: 283.42 | C9: 27 | D9: 68 | E9: 544
A10: =A9+1 -> 2014 | B10: 292.15 | C10: 33.1 | D10: 71 | E10: 713
A11: =A10+1 -> 2015 | B11: 304.98 | C11: 39.7 | D11: 70.1 | E11: 760
A12: =A11+1 -> 2016 | B12: 284.67 | C12: 47.1 | D12: 73.09 | E12: 920
A13: =A12+1 -> 2017 | B13: 389.6 | C13: 57.7 | D13: 76.01 | E13: 1040 | I13: КОРРЕЛ | J13: =CORREL(B2:B19,E2:E19) -> 0.92960897 | Q13: КОРРЕЛ | R13: =CORREL(C2:C19,E2:E19) -> 0.86391923 | Y13: КОРРЕЛ | Z13: =CORREL(D2:D19, E2:E19) -> 0.70670922
A14: =A13+1 -> 2018 | B14: 484 | C14: 64.5 | D14: 80.86 | E14: 1657 | I14: Таблица | J14: =K43/SQRT(L43*M43) -> 0.92960897 | Q14: Таблица | R14: =S43/SQRT(T43*U43) -> 0.86391923 | Y14: Таблица | Z14: =AA43/SQRT(AB43*AC43) -> 0.70670922
A15: =A14+1 -> 2019 | B15: 61.77 | C15: 64.7 | D15: 82.64 | E15: 2032 | I15: Станд. Отклонение | J15: =STDEV(B2:B19) -> 299.24741 | Q15: Станд. Отклонение | R15: =STDEV(C2:C19) -> 27.888671 | Y15: Станд. отклонение | Z15: =STDEV(D2:D19) -> 24.296451
A16: =A15+1 -> 2020 | B16: 728.51 | C16: 70.3 | D16: 84.99 | E16: 3221 | I16: Станд. ошибка оценки | J16: =J15*SQRT((1-J13^2)*(J17-1)/(J17-2)) -> 113.68108 | Q16: Станд. ошибка оценки | R16: =R15*SQRT((1-R13^2)*(R17-1)/(R17-2)) -> 14.477855 | Y16: Станд. ошибка оценки | Z16: =Z15*SQRT((1-Z13^2)*(Z17-1)/(Z17-2)) -> 17.718881
A17: =A16+1 -> 2021 | B17: 756.22 | C17: 74 | D17: 89 | E17: 3921 | I17: Кол-во строк (n) | J17: 18 | Q17: Кол-во строк (n) | R17: 18 | Y17: Кол-во строк (n) | Z17: 18
A18: =A17+1 -> 2022 | B18: 822.2 | C18: 77.7 | D18: 88.2 | E18: 4986 | I18: Коэффициент детерминации (R^2) | J18: =J13^2 -> 0.86417284 | Q18: Коэффициент детерминации (R^2) | R18: =R13^2 -> 0.74635644 | Y18: Коэффициент детерминации (R^2) | Z18: =Z13^2 -> 0.49943792
A19: =A18+1 -> 2023 | B19: 1161.6 | C19: 83.4 | D19: 89.2 | E19: 6359
G22: Таблица 1. E-com - Y, инвестиции - Х. | O22: Таблица 2. E-com - Y, доля безналичных - Х. | W22: Таблица 3. E-com - Y, пользователи интернета - Х.
G23: Xi | H23: Yi | I23: Xi − X | J23: (Yi − Y̅) | K23: (Xi − X̅) ∙ (Yi − Y̅) | L23: (Xi − X̅) 2 | M23: (Yi −Y̅) 2 | O23: Xi | P23: Yi | Q23: Xi − X | R23: (Yi − Y̅) | S23: (Xi − X̅) ∙ (Yi − Y̅) | T23: (Xi − X̅) 2 | U23: (Yi −Y̅) 2 | W23: Xi | X23: Yi | Y23: Xi − X | Z23: (Yi − Y̅) | AA23: (Xi − X̅) ∙ (Yi − Y̅) | AB23: (Xi − X̅) 2 | AC23: (Yi −Y̅) 2
G24: =B2 -> 100 | H24: =E2 -> 29.3 | I24: =G24-$G$43 -> -279.18972 | J24: =H24-$H$43 -> -1501.3089 | K24: =I24*J24 -> 419150.01 | L24: =POWER(I24, 2) -> 77946.901 | M24: =POWER(J24,2) -> 2253928.4 | O24: =C2 -> 3.25 | P24: =E2 -> 29.3 | Q24: =O24-$O$43 -> -36.680556 | R24: =P24-$P$43 -> -1501.3089 | S24: =Q24*R24 -> 55068.844 | T24: =POWER(Q24, 2) -> 1345.4632 | U24: =POWER(R24,2) -> 2253928.4 | W24: =D2 -> 17.57 | X24: =E2 -> 29.3 | Y24: =W24-$W$43 -> -45.588889 | Z24: =X24-$X$43 -> -1501.3089 | AA24: =Y24*Z24 -> 68443.004 | AB24: =POWER(Y24, 2) -> 2078.3468 | AC24: =POWER(Z24,2) -> 2253928.4
G25: =B3 -> 135.4 | H25: =E3 -> 95.35 | I25: =G25-$G$43 -> -243.78972 | J25: =H25-$H$43 -> -1435.2589 | K25: =I25*J25 -> 349901.37 | L25: =POWER(I25, 2) -> 59433.429 | M25: =POWER(J25,2) -> 2059968.1 | O25: =C3 -> 5 | P25: =E3 -> 95.35 | Q25: =O25-$O$43 -> -34.930556 | R25: =P25-$P$43 -> -1435.2589 | S25: =Q25*R25 -> 50134.39 | T25: =POWER(Q25, 2) -> 1220.1437 | U25: =POWER(R25,2) -> 2059968.1 | W25: =D3 -> 24.6 | X25: =E3 -> 95.35 | Y25: =W25-$W$43 -> -38.558889 | Z25: =X25-$X$43 -> -1435.2589 | AA25: =Y25*Z25 -> 55341.988 | AB25: =POWER(Y25, 2) -> 1486.7879 | AC25: =POWER(Z25,2) -> 2059968.1
G26: =B4 -> 150 | H26: =E4 -> 128.31 | I26: =G26-$G$43 -> -229.18972 | J26: =H26-$H$43 -> -1402.2989 | K26: =I26*J26 -> 321392.49 | L26: =POWER(I26, 2) -> 52527.929 | M26: =POWER(J26,2) -> 1966442.2 | O26: =C4 -> 9 | P26: =E4 -> 128.31 | Q26: =O26-$O$43 -> -30.930556 | R26: =P26-$P$43 -> -1402.2989 | S26: =Q26*R26 -> 43373.884 | T26: =POWER(Q26, 2) -> 956.69927 | U26: =POWER(R26,2) -> 1966442.2 | W26: =D4 -> 28.1 | X26: =E4 -> 128.31 | Y26: =W26-$W$43 -> -35.058889 | Z26: =X26-$X$43 -> -1402.2989 | AA26: =Y26*Z26 -> 49163.041 | AB26: =POWER(Y26, 2) -> 1229.1257 | AC26: =POWER(Z26,2) -> 1966442.2
G27: =B5 -> 158.34 | H27: =E5 -> 150 | I27: =G27-$G$43 -> -220.84972 | J27: =H27-$H$43 -> -1380.6089 | K27: =I27*J27 -> 304907.09 | L27: =POWER(I27, 2) -> 48774.6 | M27: =POWER(J27,2) -> 1906080.9 | O27: =C5 -> 9.3 | P27: =E5 -> 150 | Q27: =O27-$O$43 -> -30.630556 | R27: =P27-$P$43 -> -1380.6089 | S27: =Q27*R27 -> 42288.817 | T27: =POWER(Q27, 2) -> 938.23093 | U27: =POWER(R27,2) -> 1906080.9 | W27: =D5 -> 29.6 | X27: =E5 -> 150 | Y27: =W27-$W$43 -> -33.558889 | Z27: =X27-$X$43 -> -1380.6089 | AA27: =Y27*Z27 -> 46331.7 | AB27: =POWER(Y27, 2) -> 1126.199 | AC27: =POWER(Z27,2) -> 1906080.9
G28: =B6 -> 170.255 | H28: =E6 -> 260 | I28: =G28-$G$43 -> -208.93472 | J28: =H28-$H$43 -> -1270.6089 | K28: =I28*J28 -> 265474.32 | L28: =POWER(I28, 2) -> 43653.718 | M28: =POWER(J28,2) -> 1614446.9 | O28: =C6 -> 11 | P28: =E6 -> 260 | Q28: =O28-$O$43 -> -28.930556 | R28: =P28-$P$43 -> -1270.6089 | S28: =Q28*R28 -> 36759.421 | T28: =POWER(Q28, 2) -> 836.97704 | U28: =POWER(R28,2) -> 1614446.9 | W28: =D6 -> 39.9 | X28: =E6 -> 260 | Y28: =W28-$W$43 -> -23.258889 | Z28: =X28-$X$43 -> -1270.6089 | AA28: =Y28*Z28 -> 29552.951 | AB28: =POWER(Y28, 2) -> 540.97591 | AC28: =POWER(Z28,2) -> 1614446.9
G29: =B7 -> 248.64 | H29: =E7 -> 330 | I29: =G29-$G$43 -> -130.54972 | J29: =H29-$H$43 -> -1200.6089 | K29: =I29*J29 -> 156739.16 | L29: =POWER(I29, 2) -> 17043.23 | M29: =POWER(J29,2) -> 1441461.7 | O29: =C7 -> 18.7 | P29: =E7 -> 330 | Q29: =O29-$O$43 -> -21.230556 | R29: =P29-$P$43 -> -1200.6089 | S29: =Q29*R29 -> 25489.594 | T29: =POWER(Q29, 2) -> 450.73649 | U29: =POWER(R29,2) -> 1441461.7 | W29: =D7 -> 58 | X29: =E7 -> 330 | Y29: =W29-$W$43 -> -5.1588889 | Z29: =X29-$X$43 -> -1200.6089 | AA29: =Y29*Z29 -> 6193.8079 | AB29: =POWER(Y29, 2) -> 26.614135 | AC29: =POWER(Z29,2) -> 1441461.7
G30: =B8 -> 293.66 | H30: =E8 -> 405 | I30: =G30-$G$43 -> -85.529722 | J30: =H30-$H$43 -> -1125.6089 | K30: =I30*J30 -> 96273.016 | L30: =POWER(I30, 2) -> 7315.3334 | M30: =POWER(J30,2) -> 1266995.4 | O30: =C8 -> 23.3 | P30: =E8 -> 405 | Q30: =O30-$O$43 -> -16.630556 | R30: =P30-$P$43 -> -1125.6089 | S30: =Q30*R30 -> 18719.501 | T30: =POWER(Q30, 2) -> 276.57538 | U30: =POWER(R30,2) -> 1266995.4 | W30: =D8 -> 66 | X30: =E8 -> 405 | Y30: =W30-$W$43 -> 2.8411111 | Z30: =X30-$X$43 -> -1125.6089 | AA30: =Y30*Z30 -> -3197.9799 | AB30: =POWER(Y30, 2) -> 8.0719123 | AC30: =POWER(Z30,2) -> 1266995.4
G31: =B9 -> 283.42 | H31: =E9 -> 544 | I31: =G31-$G$43 -> -95.769722 | J31: =H31-$H$43 -> -986.60889 | K31: =I31*J31 -> 94487.259 | L31: =POWER(I31, 2) -> 9171.8397 | M31: =POWER(J31,2) -> 973397.1 | O31: =C9 -> 27 | P31: =E9 -> 544 | Q31: =O31-$O$43 -> -12.930556 | R31: =P31-$P$43 -> -986.60889 | S31: =Q31*R31 -> 12757.401 | T31: =POWER(Q31, 2) -> 167.19927 | U31: =POWER(R31,2) -> 973397.1 | W31: =D9 -> 68 | X31: =E9 -> 544 | Y31: =W31-$W$43 -> 4.8411111 | Z31: =X31-$X$43 -> -986.60889 | AA31: =Y31*Z31 -> -4776.2833 | AB31: =POWER(Y31, 2) -> 23.436357 | AC31: =POWER(Z31,2) -> 973397.1
G32: =B10 -> 292.15 | H32: =E10 -> 713 | I32: =G32-$G$43 -> -87.039722 | J32: =H32-$H$43 -> -817.60889 | K32: =I32*J32 -> 71164.451 | L32: =POWER(I32, 2) -> 7575.9132 | M32: =POWER(J32,2) -> 668484.3 | O32: =C10 -> 33.1 | P32: =E10 -> 713 | Q32: =O32-$O$43 -> -6.8305556 | R32: =P32-$P$43 -> -817.60889 | S32: =Q32*R32 -> 5584.7229 | T32: =POWER(Q32, 2) -> 46.656489 | U32: =POWER(R32,2) -> 668484.3 | W32: =D10 -> 71 | X32: =E10 -> 713 | Y32: =W32-$W$43 -> 7.8411111 | Z32: =X32-$X$43 -> -817.60889 | AA32: =Y32*Z32 -> -6410.9621 | AB32: =POWER(Y32, 2) -> 61.483023 | AC32: =POWER(Z32,2) -> 668484.3
G33: =B11 -> 304.98 | H33: =E11 -> 760 | I33: =G33-$G$43 -> -74.209722 | J33: =H33-$H$43 -> -770.60889 | K33: =I33*J33 -> 57186.672 | L33: =POWER(I33, 2) -> 5507.0829 | M33: =POWER(J33,2) -> 593838.06 | O33: =C11 -> 39.7 | P33: =E11 -> 760 | Q33: =O33-$O$43 -> -0.23055556 | R33: =P33-$P$43 -> -770.60889 | S33: =Q33*R33 -> 177.66816 | T33: =POWER(Q33, 2) -> 0.053155864 | U33: =POWER(R33,2) -> 593838.06 | W33: =D11 -> 70.1 | X33: =E11 -> 760 | Y33: =W33-$W$43 -> 6.9411111 | Z33: =X33-$X$43 -> -770.60889 | AA33: =Y33*Z33 -> -5348.8819 | AB33: =POWER(Y33, 2) -> 48.179023 | AC33: =POWER(Z33,2) -> 593838.06
G34: =B12 -> 284.67 | H34: =E12 -> 920 | I34: =G34-$G$43 -> -94.519722 | J34: =H34-$H$43 -> -610.60889 | K34: =I34*J34 -> 57714.583 | L34: =POWER(I34, 2) -> 8933.9779 | M34: =POWER(J34,2) -> 372843.22 | O34: =C12 -> 47.1 | P34: =E12 -> 920 | Q34: =O34-$O$43 -> 7.1694444 | R34: =P34-$P$43 -> -610.60889 | S34: =Q34*R34 -> -4377.7265 | T34: =POWER(Q34, 2) -> 51.400934 | U34: =POWER(R34,2) -> 372843.22 | W34: =D12 -> 73.09 | X34: =E12 -> 920 | Y34: =W34-$W$43 -> 9.9311111 | Z34: =X34-$X$43 -> -610.60889 | AA34: =Y34*Z34 -> -6064.0247 | AB34: =POWER(Y34, 2) -> 98.626968 | AC34: =POWER(Z34,2) -> 372843.22
G35: =B13 -> 389.6 | H35: =E13 -> 1040 | I35: =G35-$G$43 -> 10.410278 | J35: =H35-$H$43 -> -490.60889 | K35: =I35*J35 -> -5107.3748 | L35: =POWER(I35, 2) -> 108.37388 | M35: =POWER(J35,2) -> 240697.08 | O35: =C13 -> 57.7 | P35: =E13 -> 1040 | Q35: =O35-$O$43 -> 17.769444 | R35: =P35-$P$43 -> -490.60889 | S35: =Q35*R35 -> -8717.8474 | T35: =POWER(Q35, 2) -> 315.75316 | U35: =POWER(R35,2) -> 240697.08 | W35: =D13 -> 76.01 | X35: =E13 -> 1040 | Y35: =W35-$W$43 -> 12.851111 | Z35: =X35-$X$43 -> -490.60889 | AA35: =Y35*Z35 -> -6304.8693 | AB35: =POWER(Y35, 2) -> 165.15106 | AC35: =POWER(Z35,2) -> 240697.08
... G41: =B19 -> 1161.6 | H41: =E19 -> 6359 | I41: =G41-$G$43 -> 782.41028 | J41: =H41-$H$43 -> 4828.3911 | K41: =I41*J41 -> 3777782.8 | L41: =POWER(I41, 2) -> 612165.84 | M41: =POWER(J41,2) -> 23313361 | O41: =C19 -> 83.4 | P41: =E19 -> 6359 | Q41: =O41-$O$43 -> 43.469444 | R41: =P41-$P$43 -> 4828.3911 | S41: =Q41*R41 -> 209887.48 | T41: =POWER(Q41, 2) -> 1889.5926 | U41: =POWER(R41,2) -> 23313361 | W41: =D19 -> 89.2 | X41: =E19 -> 6359 | Y41: =W41-$W$43 -> 26.041111 | Z41: =X41-$X$43 -> 4828.3911 | AA41: =Y41*Z41 -> 125736.67 | AB41: =POWER(Y41, 2) -> 678.13947 | AC41: =POWER(Z41,2) -> 23313361
G43: =AVERAGE(G24:G42) -> 379.18972 | H43: =AVERAGE(H24:H42) -> 1530.6089 | K43: =SUM(K24:K42) -> 8843673 | L43: =SUM(L24:L42) -> 1522333.2 | M43: =SUM(M24:M42) -> 59450431 | O43: =AVERAGE(O24:O42) -> 39.930556 | P43: =AVERAGE(P24:P42) -> 1530.6089 | S43: =SUM(S24:S42) -> 765954.43 | T43: =SUM(T24:T42) -> 13222.226 | U43: =SUM(U24:U42) -> 59450431 | W43: =AVERAGE(W24:W42) -> 63.158889 | X43: =AVERAGE(X24:X42) -> 1530.6089 | AA43: =SUM(AA24:AA42) -> 545865.39 | AB43: =SUM(AB24:AB42) -> 10035.398 | AC43: =SUM(AC24:AC42) -> 59450431

Sheet Регресионный анализ
A1: ВЫВОД ИТОГОВ для X1
A3: Регрессионная статистика
A4: Множественный R | B4: 0.92960897
A5: R-квадрат | B5: 0.86417284
A6: Нормированный R-квадрат | B6: 0.85568365
A7: Стандартная ошибка | B7: 710.41287
A8: Наблюдения | B8: 18
A10: Дисперсионный анализ
B11: df | C11: SS | D11: MS | E11: F | F11: Значимость F
A12: Регрессия | B12: 1 | C12: 51375448 | D12: 51375448 | E12: 101.79677 | F12: 2.426439e-08
A13: Остаток | B13: 16 | C13: 8074983 | D13: 504686.44
A14: Итого | B14: 17 | C14: 59450431
B16: Коэффициенты | C16: Стандартная ошибка | D16: t-статистика | E16: P-Значение | F16: Нижние 95% | G16: Верхние 95% | H16: Нижние 95,0% | I16: Верхние 95,0%
A17: Y-пересечение | B17: -672.21362 | C17: 275.1471 | D17: -2.4431063 | E17: 0.026536211 | F17: -1255.4994 | G17: -88.927824 | H17: -1255.4994 | I17: -88.927824
A18: Переменная X 1 | B18: 5.8092885 | C18: 0.57577917 | D18: 10.089438 | E18: 2.426439e-08 | F18: 4.5886912 | G18: 7.0298859 | H18: 4.5886912 | I18: 7.0298859
A22: ВЫВОД ИТОГОВ для X2
A24: Регрессионная статистика
A25: Множественный R | B25: 0.86391923
A26: R-квадрат | B26: 0.74635644
A27: Нормированный R-квадрат | B27: 0.73050372
A28: Стандартная ошибка | B28: 970.79925
A29: Наблюдения | B29: 18
A31: Дисперсионный анализ
B32: df | C32: SS | D32: MS | E32: F | F32: Значимость F
A33: Регрессия | B33: 1 | C33: 44371212 | D33: 44371212 | E33: 47.080648 | F33: 3.824143e-06
A34: Остаток | B34: 16 | C34: 15079219 | D34: 942451.19
A35: Итого | B35: 17 | C35: 59450431
B37: Коэффициенты | C37: Стандартная ошибка | D37: t-статистика | E37: P-Значение | F37: Нижние 95% | G37: Верхние 95% | H37: Нижние 95,0% | I37: Верхние 95,0%
A38: Y-пересечение | B38: -782.54069 | C38: 407.43986 | D38: -1.9206287 | E38: 0.072782847 | F38: -1646.2746 | G38: 81.19323 | H38: -1646.2746 | I38: 81.19323
A39: Переменная X 1 | B39: 57.929311 | C39: 8.4426182 | D39: 6.8615339 | E39: 3.824143e-06 | F39: 40.03176 | G39: 75.826862 | H39: 40.03176 | I39: 75.826862
A43: ВЫВОД ИТОГОВ для X3
A45: Регрессионная статистика
A46: Множественный R | B46: 0.70670922
A47: R-квадрат | B47: 0.49943792
A48: Нормированный R-квадрат | B48: 0.46815279
A49: Стандартная ошибка | B49: 1363.7868
A50: Наблюдения | B50: 18
A52: Дисперсионный анализ
B53: df | C53: SS | D53: MS | E53: F | F53: Значимость F
A54: Регрессия | B54: 1 | C54: 29691799 | D54: 29691799 | E54: 15.964067 | F54: 0.0010418226
...

Sheet Множественная регрессия
A1: Связь между переменными | B1: Объем инвестиций в основной капитал, направленный на цифровизацию, млн. руб. | C1: Доля безналичных платежей, % | D1: Пользователи интернета, % на 100 человек | E1: Объем рынка e-commerce, млрд. руб. | K1: Пошаговый регрессионый анализ
A2: Объем инвестиций в основной капитал, направленный на цифровизацию, млн. руб. | B2: 1 | K2: ВЫВОД ИТОГОВ
A3: Доля безналичных платежей, % | B3: 0.7972919 | C3: 1
A4: Пользователи интернета, % на 100 человек | B4: 0.68694871 | C4: 0.91908108 | D4: 1 | K4: Регрессионная статистика
A5: Объем рынка e-commerce, млрд. руб. | B5: 0.92960897 | C5: 0.86391923 | D5: 0.70670922 | E5: 1 | K5: Множественный R | L5: 0.95159336
K6: R-квадрат | L6: 0.90552993
A7: Связь между переменными | B7: Объем инвестиций в основной капитал, направленный на цифровизацию, млн. руб. | C7: Доля безналичных платежей, % | D7: Пользователи интернета, % на 100 человек | E7: Объем рынка e-commerce, млрд. руб. | K7: Нормированный R-квадрат | L7: 0.89293392
A8: Объем инвестиций в основной капитал, направленный на цифровизацию, млн. руб. | B8: =IF(B2<0.7, "Связь отсутствует", "Связь есть") -> Связь есть | K8: Стандартная ошибка | L8: 611.89794
A9: Доля безналичных платежей, % | B9: =IF(B3<0.7, "Связь отсутствует", "Связь есть") -> Связь есть | C9: =IF(C3<0.7, "Связь отсутствует", "Связь есть") -> Связь есть | K9: Наблюдения | L9: 18
A10: Пользователи интернета, % на 100 человек | B10: =IF(B4<0.7, "Связь отсутствует", "Связь есть") -> Связь отсутствует | C10: =IF(C4<0.7, "Связь отсутствует", "Связь есть") -> Связь есть | D10: =IF(D4<0.7, "Связь отсутствует", "Связь есть") -> Связь есть
A11: Объем рынка e-commerce, млрд. руб. | B11: =IF(B5<0.7, "Связь отсутствует", "Связь есть") -> Связь есть | C11: =IF(C5<0.7, "Связь отсутствует", "Связь есть") -> Связь есть | D11: =IF(D5<0.7, "Связь отсутствует", "Связь есть") -> Связь есть | E11: =IF(E5<0.7, "Связь отсутствует", "Связь есть") -> Связь есть | K11: Дисперсионный анализ
L12: df | M12: SS | N12: MS | O12: F | P12: Значимость F
A13: ВЫВОД ИТОГОВ | K13: Регрессия | L13: 2 | M13: 53834145 | N13: 26917072 | O13: 71.890224 | P13: 2.0639862e-08
A14: Регрессионная статистика | K14: Остаток | L14: 15 | M14: 5616286.4 | N14: 374419.09
A15: Множественный R | B15: 0.9629473 | K15: Итого | L15: 17 | M15: 59450431
A16: R-квадрат | B16: 0.9272675
A17: Нормированный R-квадрат | B17: 0.91168197 | L17: Коэффициенты | M17: Стандартная ошибка | N17: t-статистика | O17: P-Значение | P17: Нижние 95% | Q17: Верхние 95% | R17: Нижние 95,0% | S17: Верхние 95,0%
A18: Стандартная ошибка | B18: 555.74778 | K18: Y-пересечение | L18: -937.78467 | M18: 258.66061 | N18: -3.625541 | O18: 0.002491693 | P18: -1489.1067 | Q18: -386.46262 | R18: -1489.1067 | S18: -386.46262
A19: Наблюдения | B19: 18 | K19: Переменная X 1 | L19: 4.1306001 | M19: 0.82163564 | N19: 5.0272893 | O19: 0.00015021951 | P19: 2.3793252 | Q19: 5.881875 | R19: 2.3793252 | S19: 5.881875
K20: Переменная X 2 | L20: 22.592034 | M20: 8.8162085 | N20: 2.5625567 | O20: 0.021651919 | P20: 3.8007302 | Q20: 41.383337 | R20: 3.8007302 | S20: 41.383337
A21: Дисперсионный анализ
B22: df | C22: SS | D22: MS | E22: F | F22: Значимость F
A23: Регрессия | B23: 3 | C23: 55126453 | D23: 18375484 | E23: 59.495391 | F23: 3.2736733e-08
A24: Остаток | B24: 14 | C24: 4323978.3 | D24: 308855.59 | K24: ВЫВОД ИТОГОВ
A25: Итого | B25: 17 | C25: 59450431
K26: Регрессионная статистика
B27: Коэффициенты | C27: Стандартная ошибка | D27: t-статистика | E27: P-Значение | F27: Нижние 95% | G27: Верхние 95% | H27: Нижние 95,0% | I27: Верхние 95,0% | K27: Множественный R | L27: 0.97571
A28: Y-пересечение | B28: -11.300111 | C28: 510.2323 | D28: -0.022146993 | E28: 0.98264326 | F28: -1105.6395 | G28: 1083.0393 | H28: -1105.6395 | I28: 1083.0393 | K28: R-квадрат | L28: 0.95201
A29: Переменная X 1 | B29: 3.8308882 | C29: 0.76048742 | D29: 5.0374116 | E29: 0.00018149398 | F29: 2.1998049 | G29: 5.4619715 | H29: 2.1998049 | I29: 5.4619715 | K29: Нормированный R-квадрат | L29: 0.94172643
A30: Переменная X 2 | B30: 48.653853 | C30: 15.048098 | D30: 3.2332228 | E30: 0.0060099799 | F30: 16.378893 | G30: 80.928813 | H30: 16.378893 | I30: 80.928813 | K30: Стандартная ошибка | L30: 451.42838
A31: Переменная X 3 | B31: -29.346618 | C31: 14.346725 | D31: -2.0455274 | E31: 0.06007072 | F31: -60.117282 | G31: 1.424046 | H31: -60.117282 | I31: 1.424046 | K31: Наблюдения | L31: 18
A33: Выводы: | K33: Дисперсионный анализ
A34: Сдвиг a=-11,3 обозначает, что объем рынка e-commerce при нулевых остальных показателях понизится на 11,3 млрд. руб., что является маловероятным. Коэффициент регрессии по объемам инвестиций на цифровизацию составляет 3,83 , что обозначает, что при увеличении инвестиций на 1 млн. руб. объем рынка e-commerce вырастет на 2,582 млн. руб (остальные показатели не изменяются). F-статистика равна 59,4953909 с p-value 3,27367E-08, что указывает на то, что регрессионная модель является статистически высоко значимой. Однако t-тест подтверждает значимость переменных X1 и X2 | L34: df | M34: SS | N34: MS | O34: F | P34: Значимость F
K35: Регрессия | L35: 3 | M35: 56597405 | N35: 18865802 | O35: 92.575815 | P35: 1.8028389e-09
K36: Остаток | L36: 14 | M36: 2853026.2 | N36: 203787.58
K37: Итого | L37: 17 | M37: 59450431
L39: Коэффициенты | M39: Стандартная ошибка | N39: t-статистика | O39: P-Значение | P39: Нижние 95% | Q39: Верхние 95% | R39: Нижние 95,0% | S39: Верхние 95,0%
K40: Y-пересечение | L40: 2563.5821 | M40: 969.81727 | N40: 2.6433661 | O40: 0.019277162 | P40: 483.53089 | Q40: 4643.6332 | R40: 483.53089 | S40: 4643.6332
K41: Переменная X 1 | L41: -19.356206 | M41: 13.117809 | N41: -1.475567 | O41: 0.16219425 | P41: -47.491108 | Q41: 8.7786968 | R41: -47.491108 | S41: 8.7786968
K42: Переменная X 2 | L42: 0.37235266 | M42: 0.10111892 | N42: 3.6823243 | O42: 0.0024620087 | P42: 0.15547414 | Q42: 0.58923118 | R42: 0.15547414 | S42: 0.58923118
...

Sheet Проверка гипотез
A1: Год | B1: Объем инвестиций в основной капитал, направленный на цифровизацию, млрд. руб. | C1: Доля безналичных платежей, % | D1: X2X3 | E1: Объем рынка e-commerce, млрд. руб. | I1: Вывод: | J1: МНК применим с ограничениями к данным, т. к. у них отсутсвует однородность дисперсий, однако разница между R и F не существенная
A2: 2006 | B2: 100 | C2: 3.25 | D2: ='Корреляционный анализ'!C2*'Корреляционный анализ'!D2 -> 57.1025 | E2: 29.3
A3: 2007 | B3: 135.4 | C3: 5 | D3: ='Корреляционный анализ'!C3*'Корреляционный анализ'!D3 -> 123 | E3: 95.35
A4: 2008 | B4: 150 | C4: 9 | D4: ='Корреляционный анализ'!C4*'Корреляционный анализ'!D4 -> 252.9 | E4: 128.31
A5: 2009 | B5: 158.34 | C5: 9.3 | D5: ='Корреляционный анализ'!C5*'Корреляционный анализ'!D5 -> 275.28 | E5: 150
A6: 2010 | B6: 170.255 | C6: 11 | D6: ='Корреляционный анализ'!C6*'Корреляционный анализ'!D6 -> 438.9 | E6: 260
A7: 2011 | B7: 248.64 | C7: 18.7 | D7: ='Корреляционный анализ'!C7*'Корреляционный анализ'!D7 -> 1084.6 | E7: 330
A8: =A7+1 -> 2012 | B8: 293.66 | C8: 23.3 | D8: ='Корреляционный анализ'!C8*'Корреляционный анализ'!D8 -> 1537.8 | E8: 405
A9: =A8+1 -> 2013 | B9: 283.42 | C9: 27 | D9: ='Корреляционный анализ'!C9*'Корреляционный анализ'!D9 -> 1836 | E9: 544
A10: =A9+1 -> 2014 | B10: 292.15 | C10: 33.1 | D10: ='Корреляционный анализ'!C10*'Корреляционный анализ'!D10 -> 2350.1 | E10: 713
A11: =A10+1 -> 2015 | B11: 304.98 | C11: 39.7 | D11: ='Корреляционный анализ'!C11*'Корреляционный анализ'!D11 -> 2782.97 | E11: 760
A12: =A11+1 -> 2016 | B12: 284.67 | C12: 47.1 | D12: ='Корреляционный анализ'!C12*'Корреляционный анализ'!D12 -> 3442.539 | E12: 920
A13: =A12+1 -> 2017 | B13: 389.6 | C13: 57.7 | D13: ='Корреляционный анализ'!C13*'Корреляционный анализ'!D13 -> 4385.777 | E13: 1040
A14: =A13+1 -> 2018 | B14: 484 | C14: 64.5 | D14: ='Корреляционный анализ'!C14*'Корреляционный анализ'!D14 -> 5215.47 | E14: 1657
A15: =A14+1 -> 2019 | B15: 61.77 | C15: 64.7 | D15: ='Корреляционный анализ'!C15*'Корреляционный анализ'!D15 -> 5346.808 | E15: 2032
A16: =A15+1 -> 2020 | B16: 728.51 | C16: 70.3 | D16: ='Корреляционный анализ'!C16*'Корреляционный анализ'!D16 -> 5974.797 | E16: 3221
A17: =A16+1 -> 2021 | B17: 756.22 | C17: 74 | D17: ='Корреляционный анализ'!C17*'Корреляционный анализ'!D17 -> 6586 | E17: 3921
A18: =A17+1 -> 2022 | B18: 822.2 | C18: 77.7 | D18: ='Корреляционный анализ'!C18*'Корреляционный анализ'!D18 -> 6853.14 | E18: 4986
A19: =A18+1 -> 2023 | B19: 1161.6 | C19: 83.4 | D19: ='Корреляционный анализ'!C19*'Корреляционный анализ'!D19 -> 7439.28 | E19: 6359
A21: По итогам 1-2 практических работ была получена наилучшая регрессионая модель с Х1,X2 и Х2X3
A23: Гипотеза 1: Остатки предсатвляют собой случайные величины | K23: Гипотеза 2: У остатков нулевая средняя величина | P23: Гипотеза 3: для каждого значения фактора х остатки имеют одинаковыую дисперсию | AE23: Гипотеза 4: У остатков для каждого значения х отсутсвует автокорреляция | AJ23: Гипотеза 5: Остатки подчиняются нормальному закону распределения
A24: ВЫВОД ИТОГОВ | K24: СРЗНАЧ(C4:C15) | M24: =AVERAGE(C50:C67) -> -1.6042476e-12 | N24: Среднее значение | P24: ВЫВОД ОСТАТКА | AE24: Наблюдение | AF24: Предсказанное Объем рынка e-commerce, млрд. руб. | AG24: Остатки | AH24: Остатки (n-1) со смещением
K25: СТАНДОТКЛОН.В(С4:С15) | M25: =STDEV(C50:C67) -> 355.90517 | N25: Среднее квадратическое отклонение | AE25: 1 | AF25: 353.40234 | AG25: -324.10234
A26: Регрессионная статистика | K26: С25*КОРЕНЬ(кол-во показателей в выборке)/С19 | M26: =M24*SQRT(18)/M25 -> -1.9123763e-14 | N26: Zнабл | P26: Наблюдение | Q26: Предсказанное Объем рынка e-commerce, млрд. руб. | R26: Остатки | S26: Стандартные остатки | T26: Квадраты остатков | U26: X1 | V26: X2 | W26: X2X3 | AE26: 2 | AF26: 266.49124 | AG26: -171.14124 | AH26: -324.10234
A27: Множественный R | B27: 0.98172238 | K27: НОРМ.СТ.ОБР(1-0,05/2) | M27: =_xlfn.NORM.S.INV(1-0.05/2) -> 1.959964 | N27: Zтабл | P27: 1 | Q27: 353.40234 | R27: -324.10234 | S27: -0.91064241 | T27: =R27*R27 -> 105042.33 | U27: 100 | V27: 3.25 | W27: 57.1025 | AE27: 3 | AF27: -143.91527 | AG27: 272.22527 | AH27: -171.14124
A28: R-квадрат | B28: 0.96377883 | P28: 2 | Q28: 266.49124 | R28: -171.14124 | S28: -0.48086192 | T28: =R28*R28 -> 29289.325 | U28: 135.4 | V28: 5 | W28: 123 | AE28: 4 | AF28: -125.99512 | AG28: 275.99512 | AH28: 272.22527
A29: Нормированный R-квадрат | B29: 0.95601715 | L29: Zнабл<Zтабл | M29: =IF(M26<M27, TRUE, FALSE) -> TRUE | P29: 3 | Q29: -143.91527 | R29: 272.22527 | S29: 0.76488148 | T29: =R29*R29 -> 74106.597 | U29: 150 | V29: 9 | W29: 252.9 | AE29: 5 | AF29: -19.392547 | AG29: 279.39255 | AH29: 275.99512
A30: Стандартная ошибка | B30: 392.18839 | P30: 4 | Q30: -125.99512 | R30: 275.99512 | S30: 0.77547378 | T30: =R30*R30 -> 76173.309 | U30: 158.34 | V30: 9.3 | W30: 275.28 | AE30: 6 | AF30: 287.49141 | AG30: 42.50859 | AH30: 279.39255
A31: Наблюдения | B31: 18 | P31: 5 | Q31: -19.392547 | R31: 279.39255 | S31: 0.78501964 | T31: =R31*R31 -> 78060.195 | U31: 170.255 | V31: 11 | W31: 438.9 | AE31: 7 | AF31: 632.69807 | AG31: -227.69807 | AH31: 42.50859 | AJ31: Остатки подчиняются нормальному закону распределения
P32: 6 | Q32: 287.49141 | R32: 42.50859 | S32: 0.11943797 | T32: =R32*R32 -> 1806.9802 | U32: 248.64 | V32: 18.7 | W32: 1084.6 | AE32: 8 | AF32: 634.33574 | AG32: -90.335738 | AH32: -227.69807
A33: Дисперсионный анализ | P33: 7 | Q33: 632.69807 | R33: -227.69807 | S33: -0.63977175 | T33: =R33*R33 -> 51846.412 | U33: 293.66 | V33: 23.3 | W33: 1537.8 | AE33: 9 | AF33: 754.48018 | AG33: -41.480183 | AH33: -90.335738
B34: df | C34: SS | D34: MS | E34: F | F34: Значимость F | P34: 8 | Q34: 634.33574 | R34: -90.335738 | S34: -0.25381969 | T34: =R34*R34 -> 8160.5456 | U34: 283.42 | V34: 27 | W34: 1836 | AE34: 10 | AF34: 588.62084 | AG34: 171.37916 | AH34: -41.480183
A35: Регрессия | B35: 3 | C35: 57297067 | D35: 19099022 | E35: 124.17143 | F35: 2.5290742e-10 | P35: 9 | Q35: 754.48018 | R35: -41.480183 | S35: -0.11654841 | T35: =R35*R35 -> 1720.6055 | U35: 292.15 | V35: 33.1 | W35: 2350.1 | AE35: 11 | AF35: 747.99239 | AG35: 172.00761 | AH35: 171.37916
A36: Остаток | B36: 14 | C36: 2153364.3 | D36: 153811.73 | P36: 10 | Q36: 588.62084 | R36: 171.37916 | S36: 0.4815304 | T36: =R36*R36 -> 29370.816 | U36: 304.98 | V36: 39.7 | W36: 2782.97 | AE36: 12 | AF36: 1297.1986 | AG36: -257.19857 | AH36: 172.00761
A37: Итого | B37: 17 | C37: 59450431 | P37: 11 | Q37: 747.99239 | R37: 172.00761 | S37: 0.48329618 | T37: =R37*R37 -> 29586.616 | U37: 284.67 | V37: 47.1 | W37: 3442.539 | AE37: 13 | AF37: 2268.6844 | AG37: -611.68441 | AH37: -257.19857
P38: 12 | Q38: 1297.1986 | R38: -257.19857 | S38: -0.72266041 | T38: =R38*R38 -> 66151.106 | U38: 389.6 | V38: 57.7 | W38: 4385.777 | AE38: 14 | AF38: 1531.015 | AG38: 500.98498 | AH38: -611.68441
B39: Коэффициенты | C39: Стандартная ошибка | D39: t-статистика | E39: P-Значение | F39: Нижние 95% | G39: Верхние 95% | H39: Нижние 95,0% | I39: Верхние 95,0% | P39: 13 | Q39: 2268.6844 | R39: -611.68441 | S39: -1.7186725 | T39: =R39*R39 -> 374157.82 | U39: 484 | V39: 64.5 | W39: 5215.47 | AE39: 15 | AF39: 3621.9478 | AG39: -400.94778 | AH39: 500.98498
A40: Y-пересечение | B40: 592.68701 | C40: 362.66245 | D40: 1.6342663 | E40: 0.1244808 | F40: -185.14658 | G40: 1370.5206 | H40: -185.14658 | I40: 1370.5206 | P40: 14 | Q40: 1531.015 | R40: 500.98498 | S40: 1.4076361 | T40: =R40*R40 -> 250985.95 | U40: 61.77 | V40: 64.7 | W40: 5346.808 | AE40: 16 | AF40: 4486.9556 | AG40: -565.95564 | AH40: -400.94778
A41: Переменная X 1 | B41: 2.4230025 | C41: 0.63784008 | D41: 3.7987618 | E41: 0.0019555843 | F41: 1.0549716 | G41: 3.7910334 | H41: 1.0549716 | I41: 3.7910334 | P41: 15 | Q41: 3621.9478 | R41: -400.94778 | S41: -1.1265579 | T41: =R41*R41 -> 160759.13 | U41: 728.51 | V41: 70.3 | W41: 5974.797 | AE41: 17 | AF41: 4596.7251 | AG41: 389.27493 | AH41: -565.95564
A42: Переменная X 2 | B42: -191.48244 | C42: 45.469276 | D42: -4.2112489 | E42: 0.00087128378 | F42: -289.00434 | G42: -93.960541 | H42: -289.00434 | I42: -93.960541 | P42: 16 | Q42: 4486.9556 | R42: -565.95564 | S42: -1.5901866 | T42: =R42*R42 -> 320305.78 | U42: 756.22 | V42: 74 | W42: 6586 | AE42: 18 | AF42: 5772.2242 | AG42: 586.77578 | AH42: 389.27493
...

Sheet Анализ временных рядов
A1: Номер периода | B1: Год | C1: Объем рынка e-commerce, трлн. руб. | E1: Выборка была разделена на 4 периода по 5 лет, чтобы детально рассмотреть максимально возможное количество периодов
A2: t | C2: Y
A3: 1 | B3: 2006 | C3: 29.3
A4: 2 | B4: 2007 | C4: 95.35 | E4: Мультипликативная
A5: 3 | B5: 2008 | C5: 128.31
A6: 4 | B6: 2009 | C6: 150
A7: 5 | B7: 2010 | C7: 260
A8: 6 | B8: 2011 | C8: 330
A9: 7 | B9: =B8+1 -> 2012 | C9: 405
A10: 8 | B10: =B9+1 -> 2013 | C10: 544
A11: 9 | B11: =B10+1 -> 2014 | C11: 713
A12: 10 | B12: =B11+1 -> 2015 | C12: 760
A13: 11 | B13: =B12+1 -> 2016 | C13: 920
A14: 12 | B14: =B13+1 -> 2017 | C14: 1040
A15: 13 | B15: =B14+1 -> 2018 | C15: 1657
A16: 14 | B16: =B15+1 -> 2019 | C16: 2032
A17: 15 | B17: =B16+1 -> 2020 | C17: 3221
A18: 16 | B18: =B17+1 -> 2021 | C18: 3921
A19: 17 | B19: =B18+1 -> 2022 | C19: 4986
A20: 18 | B20: =B19+1 -> 2023 | C20: 6359
A22: Номер периода | B22: Год | C22: Объем рынка e-commerce, млрд. руб. | D22: Итого за 5 лет | E22: Скользящая средняя (5 лет) | F22: Центрированная скользящая | G22: Оценка сезонной компоненты
A23: t | C23: Y
A24: 1 | B24: 2006 | C24: 29.3
A25: 2 | B25: 2007 | C25: 95.35 | D25: =SUM(C24:C28) -> 662.96 | E25: =D25/5 -> 132.592
A26: 3 | B26: 2008 | C26: 128.31 | D26: =SUM(C25:C29) -> 963.66 | E26: =D26/5 -> 192.732 | F26: =SUM(E25:E26)/2 -> 162.662 | G26: =E26/F26 -> 1.1848619
A27: 4 | B27: 2009 | C27: 150 | D27: =SUM(C26:C30) -> 1273.31 | E27: =D27/5 -> 254.662 | F27: =SUM(E26:E27)/2 -> 223.697 | G27: =E27/F27 -> 1.1384239
A28: 5 | B28: 2010 | C28: 260 | D28: =SUM(C27:C31) -> 1689 | E28: =D28/5 -> 337.8 | F28: =SUM(E27:E28)/2 -> 296.231 | G28: =E28/F28 -> 1.1403263
A29: 6 | B29: 2011 | C29: 330 | D29: =SUM(C28:C32) -> 2252 | E29: =D29/5 -> 450.4 | F29: =SUM(E28:E29)/2 -> 394.1 | G29: =E29/F29 -> 1.1428571
A30: 7 | B30: =B29+1 -> 2012 | C30: 405 | D30: =SUM(C29:C33) -> 2752 | E30: =D30/5 -> 550.4 | F30: =SUM(E29:E30)/2 -> 500.4 | G30: =E30/F30 -> 1.0999201
A31: 8 | B31: =B30+1 -> 2013 | C31: 544 | D31: =SUM(C30:C34) -> 3342 | E31: =D31/5 -> 668.4 | F31: =SUM(E30:E31)/2 -> 609.4 | G31: =E31/F31 -> 1.0968165
A32: 9 | B32: =B31+1 -> 2014 | C32: 713 | D32: =SUM(C31:C35) -> 3977 | E32: =D32/5 -> 795.4 | F32: =SUM(E31:E32)/2 -> 731.9 | G32: =E32/F32 -> 1.0867605
A33: 10 | B33: =B32+1 -> 2015 | C33: 760 | D33: =SUM(C32:C36) -> 5090 | E33: =D33/5 -> 1018 | F33: =SUM(E32:E33)/2 -> 906.7 | G33: =E33/F33 -> 1.1227528
A34: 11 | B34: =B33+1 -> 2016 | C34: 920 | D34: =SUM(C33:C37) -> 6409 | E34: =D34/5 -> 1281.8 | F34: =SUM(E33:E34)/2 -> 1149.9 | G34: =E34/F34 -> 1.1147056
A35: 12 | B35: =B34+1 -> 2017 | C35: 1040 | D35: =SUM(C34:C38) -> 8870 | E35: =D35/5 -> 1774 | F35: =SUM(E34:E35)/2 -> 1527.9 | G35: =E35/F35 -> 1.1610708
A36: 13 | B36: =B35+1 -> 2018 | C36: 1657 | D36: =SUM(C35:C39) -> 11871 | E36: =D36/5 -> 2374.2 | F36: =SUM(E35:E36)/2 -> 2074.1 | G36: =E36/F36 -> 1.1446893
A37: 14 | B37: =B36+1 -> 2019 | C37: 2032 | D37: =SUM(C36:C40) -> 15817 | E37: =D37/5 -> 3163.4 | F37: =SUM(E36:E37)/2 -> 2768.8 | G37: =E37/F37 -> 1.1425166
A38: 15 | B38: =B37+1 -> 2020 | C38: 3221 | D38: =SUM(C37:C41) -> 20519 | E38: =D38/5 -> 4103.8 | F38: =SUM(E37:E38)/2 -> 3633.6 | G38: =E38/F38 -> 1.1294033
A39: 16 | B39: =B38+1 -> 2021 | C39: 3921 | D39: - | E39: - | F39: - | G39: -
A40: 17 | B40: =B39+1 -> 2022 | C40: 4986 | D40: - | E40: - | F40: - | G40: -
A41: 18 | B41: =B40+1 -> 2023 | C41: 6359 | D41: - | E41: - | F41: - | G41: -
...
